<?xml version="1.0" ?>
<robot name="zephyr_delta_wing_rudder">
  <joint name="zephyr_delta_wing_rudder__zephyr/imu_joint" type="fixed">
    <parent link="zephyr_delta_wing_rudder__wing"/>
    <child link="zephyr_delta_wing_rudder__zephyr/imu_link"/>
    <origin xyz="0      0      0.02577" rpy="0 0 0"/>
    <axis xyz="0 0 1"/>
    <limit lower="0.0" upper="0.0" effort="0.0" velocity="0.0"/>
  </joint>
  <joint name="zephyr_delta_wing_rudder__propeller_1_joint" type="revolute">
    <parent link="zephyr_delta_wing_rudder__wing"/>
    <child link="zephyr_delta_wing_rudder__propeller_1"/>
    <origin xyz="0.35    -0.32     0.03377" rpy="0      1.57079 0"/>
    <axis xyz="0 -1  0"/>
    <limit lower="-1e+16" upper="1e+16" effort="0.0" velocity="0.0"/>
  </joint>
  <joint name="zephyr_delta_wing_rudder__propeller_2_joint" type="revolute">
    <parent link="zephyr_delta_wing_rudder__wing"/>
    <child link="zephyr_delta_wing_rudder__propeller_2"/>
    <origin xyz="-0.35    -0.32     0.03377" rpy="0      1.57079 0"/>
    <axis xyz="0 1 0"/>
    <limit lower="-1e+16" upper="1e+16" effort="0.0" velocity="0.0"/>
  </joint>
  <joint name="zephyr_delta_wing_rudder__flap_left_joint" type="revolute">
    <parent link="zephyr_delta_wing_rudder__wing"/>
    <child link="zephyr_delta_wing_rudder__flap_left"/>
    <origin xyz="0.453   0.199   0.03277" rpy="0 0 0"/>
    <axis xyz="1      0.33032 0"/>
    <limit lower="-0.524" upper="0.524" effort="0.0" velocity="0.0"/>
  </joint>
  <joint name="zephyr_delta_wing_rudder__flap_right_joint" type="revolute">
    <parent link="zephyr_delta_wing_rudder__wing"/>
    <child link="zephyr_delta_wing_rudder__flap_right"/>
    <origin xyz="-0.453    0.199    0.03277" rpy="0 0 0"/>
    <axis xyz="1      -0.33032  0"/>
    <limit lower="-0.524" upper="0.524" effort="0.0" velocity="0.0"/>
  </joint>
  <link name="zephyr_delta_wing_rudder__wing">
    <inertial>
      <mass value="1.5"/>
      <origin xyz="0   -0.12  0" rpy="0 0 0"/>
      <inertia ixx="0.083137104" ixy="0" ixz="0" iyy="0.387382402" iyz="0" izz="0.469845106"/>
    </inertial>
    <collision name="zephyr_delta_wing_rudder__body_collision">
      <origin xyz="0      0      0.02577" rpy="0 0 0"/>
      <geometry>
        <mesh filename="package://kuav_simulation/models/zephyr_delta_wing_rudder/meshes/wing.dae OR kuav_simulation/models/zephyr_delta_wing/meshes/wing.dae" scale="1.0 1.0 1.0"/>
      </geometry>
    </collision>
    <collision name="zephyr_delta_wing_rudder__right_rudder_collision">
      <origin xyz="-0.76435  0.33918  0.02777" rpy="-0.03  0    0"/>
      <geometry>
        <box size=".005 0.12993 .12688"/>
      </geometry>
    </collision>
    <collision name="zephyr_delta_wing_rudder__left_rudder_collision">
      <origin xyz="0.76435 0.33918 0.02777" rpy="-0.03  0    0"/>
      <geometry>
        <box size=".005 0.12993 .12688"/>
      </geometry>
    </collision>
    <visual name="zephyr_delta_wing_rudder__visual">
      <origin xyz="0      0      0.02577" rpy="0 0 0"/>
      <geometry>
        <mesh filename="package://kuav_simulation/models/zephyr_delta_wing_rudder/meshes/wing.dae OR kuav_simulation/models/zephyr_delta_wing/meshes/wing.dae" scale="1.0 1.0 1.0"/>
      </geometry>
    </visual>
  </link>
  <link name="zephyr_delta_wing_rudder__zephyr/imu_link">
    <inertial>
      <mass value="0.15"/>
      <origin xyz="0 0 0" rpy="0 0 0"/>
      <inertia ixx="0.00001" ixy="0" ixz="0" iyy="0.00002" iyz="0" izz="0.00002"/>
    </inertial>
  </link>
  <link name="zephyr_delta_wing_rudder__propeller_1">
    <inertial>
      <mass value=".05"/>
      <origin xyz="0 0 0" rpy="0 0 0"/>
      <inertia ixx="0.000367571" ixy="0" ixz="0" iyy="0.00036985" iyz="0" izz="0.000003187"/>
    </inertial>
    <collision name="zephyr_delta_wing_rudder__blade1">
      <origin xyz="0     0     0.0742" rpy="0  0  0.3"/>
      <geometry>
        <box size="0.02561 0.00541 0.14841"/>
      </geometry>
    </collision>
    <collision name="zephyr_delta_wing_rudder__blade2">
      <origin xyz="0      0     -0.0742" rpy="0   0  -0.3"/>
      <geometry>
        <box size="0.02561 0.00541 0.14841"/>
      </geometry>
    </collision>
    <visual name="zephyr_delta_wing_rudder__visual">
      <origin xyz="0 0 0" rpy="0 0 0"/>
      <geometry>
        <mesh filename="package://kuav_simulation/models/zephyr_delta_wing_rudder/meshes/wing.dae OR kuav_simulation/models/zephyr_delta_wing/meshes/wing.dae" scale="1.0 1.0 1.0"/>
      </geometry>
    </visual>
  </link>
  <link name="zephyr_delta_wing_rudder__propeller_2">
    <inertial>
      <mass value=".05"/>
      <origin xyz="0 0 0" rpy="0 0 0"/>
      <inertia ixx="0.000367571" ixy="0" ixz="0" iyy="0.00036985" iyz="0" izz="0.000003187"/>
    </inertial>
    <collision name="zephyr_delta_wing_rudder__blade1">
      <origin xyz="0     0     0.0742" rpy="0   0  -0.3"/>
      <geometry>
        <box size="0.02561 0.00541 0.14841"/>
      </geometry>
    </collision>
    <collision name="zephyr_delta_wing_rudder__blade2">
      <origin xyz="0      0     -0.0742" rpy="0  0  0.3"/>
      <geometry>
        <box size="0.02561 0.00541 0.14841"/>
      </geometry>
    </collision>
    <visual name="zephyr_delta_wing_rudder__visual">
      <origin xyz="0 0 0" rpy="0 0 0"/>
      <geometry>
        <mesh filename="package://kuav_simulation/models/zephyr_delta_wing_rudder/meshes/wing.dae OR kuav_simulation/models/zephyr_delta_wing/meshes/wing.dae" scale="-1 1 1"/>
      </geometry>
    </visual>
  </link>
  <link name="zephyr_delta_wing_rudder__flap_left">
    <inertial>
      <mass value=".1"/>
      <origin xyz="0 0 0" rpy="0      0      0.32445"/>
      <inertia ixx="0.000102319" ixy="0" ixz="0" iyy="0.00334417" iyz="0" izz="0.003446072"/>
    </inertial>
    <collision name="zephyr_delta_wing_rudder__collision">
      <origin xyz="-0.01  0.05  0" rpy="0      0      0.32445"/>
      <geometry>
        <box size="0.633463031 0.110694312 0.005"/>
      </geometry>
    </collision>
    <visual name="zephyr_delta_wing_rudder__visual">
      <origin xyz="0   0.04 0" rpy="0 0 0"/>
      <geometry>
        <mesh filename="package://kuav_simulation/models/zephyr_delta_wing_rudder/meshes/wing.dae OR kuav_simulation/models/zephyr_delta_wing/meshes/wing.dae" scale="1.0 1.0 1.0"/>
      </geometry>
    </visual>
  </link>
  <link name="zephyr_delta_wing_rudder__flap_right">
    <inertial>
      <mass value=".1"/>
      <origin xyz="0 0 0" rpy="0       0      -0.32445"/>
      <inertia ixx="0.000102319" ixy="0" ixz="0" iyy="0.00334417" iyz="0" izz="0.003446072"/>
    </inertial>
    <collision name="zephyr_delta_wing_rudder__collision">
      <origin xyz="0.01 0.05 0" rpy="0       0      -0.32445"/>
      <geometry>
        <box size="0.633463031 0.110694312 0.005"/>
      </geometry>
    </collision>
    <visual name="zephyr_delta_wing_rudder__visual">
      <origin xyz="0   0.04 0" rpy="0 0 0"/>
      <geometry>
        <mesh filename="package://kuav_simulation/models/zephyr_delta_wing_rudder/meshes/wing.dae OR kuav_simulation/models/zephyr_delta_wing/meshes/wing.dae" scale="1.0 1.0 1.0"/>
      </geometry>
    </visual>
  </link>
</robot>
